{"uid":"9dff96bb821c3908","name":"Create new user in data base","fullName":"test.test_create_custuner.TestCreateCostuner#test_create_new_user","historyId":"34e2d2438918fa549b75b0c3a7328b57","time":{"start":1691955957117,"stop":1691955957117,"duration":0},"status":"broken","statusMessage":"selenium.common.exceptions.WebDriverException: Message: Service /root/.wdm/drivers/chromedriver/linux64/114.0.5735.90/chromedriver unexpectedly exited. Status code was: 255","statusTrace":"request = <SubRequest 'driver' for <Function test_create_new_user>>\n\n    @pytest.fixture(scope='class', autouse=True)\n    def driver(request):\n        options = Options()\n        options.add_argument(\"--no-sandbox\")\n        options.add_argument(\"window-size=2560,1600\")\n        options.add_argument(\"--headless\")\n        options.add_argument(\"--disable-gpu\")\n        service = Service(ChromeDriverManager().install())\n>       driver = webdriver.Chrome(service=service, options=options)\n\nconftest.py:16: \n_ _ _ _ _ _ _ _ _ _ _ _ _ _ _ _ _ _ _ _ _ _ _ _ _ _ _ _ _ _ _ _ _ _ _ _ _ _ _ _ \n/usr/local/lib/python3.12/site-packages/selenium/webdriver/chrome/webdriver.py:45: in __init__\n    super().__init__(\n/usr/local/lib/python3.12/site-packages/selenium/webdriver/chromium/webdriver.py:53: in __init__\n    self.service.start()\n/usr/local/lib/python3.12/site-packages/selenium/webdriver/common/service.py:109: in start\n    self.assert_process_still_running()\n_ _ _ _ _ _ _ _ _ _ _ _ _ _ _ _ _ _ _ _ _ _ _ _ _ _ _ _ _ _ _ _ _ _ _ _ _ _ _ _ \n\nself = <selenium.webdriver.chrome.service.Service object at 0xffffb6698470>\n\n    def assert_process_still_running(self) -> None:\n        \"\"\"Check if the underlying process is still running.\"\"\"\n        return_code = self.process.poll()\n        if return_code:\n>           raise WebDriverException(f\"Service {self._path} unexpectedly exited. Status code was: {return_code}\")\nE           selenium.common.exceptions.WebDriverException: Message: Service /root/.wdm/drivers/chromedriver/linux64/114.0.5735.90/chromedriver unexpectedly exited. Status code was: 255\n\n/usr/local/lib/python3.12/site-packages/selenium/webdriver/common/service.py:122: WebDriverException","flaky":false,"newFailed":false,"newBroken":false,"newPassed":false,"retriesCount":0,"retriesStatusChange":false,"beforeStages":[{"name":"_session_faker","time":{"start":1691955954534,"stop":1691955954543,"duration":9},"status":"passed","steps":[],"attachments":[],"parameters":[],"stepsCount":0,"attachmentsCount":0,"shouldDisplayMessage":false,"hasContent":false},{"name":"driver","time":{"start":1691955957118,"stop":1691955959570,"duration":2452},"status":"broken","statusMessage":"selenium.common.exceptions.WebDriverException: Message: Service /root/.wdm/drivers/chromedriver/linux64/114.0.5735.90/chromedriver unexpectedly exited. Status code was: 255\n\n","statusTrace":"  File \"/usr/local/lib/python3.12/site-packages/pluggy/_callers.py\", line 80, in _multicall\n    res = hook_impl.function(*args)\n          ^^^^^^^^^^^^^^^^^^^^^^^^^\n  File \"/usr/local/lib/python3.12/site-packages/_pytest/fixtures.py\", line 1123, in pytest_fixture_setup\n    result = call_fixture_func(fixturefunc, request, kwargs)\n             ^^^^^^^^^^^^^^^^^^^^^^^^^^^^^^^^^^^^^^^^^^^^^^^\n  File \"/usr/local/lib/python3.12/site-packages/_pytest/fixtures.py\", line 895, in call_fixture_func\n    fixture_result = next(generator)\n                     ^^^^^^^^^^^^^^^\n  File \"/app/conftest.py\", line 16, in driver\n    driver = webdriver.Chrome(service=service, options=options)\n             ^^^^^^^^^^^^^^^^^^^^^^^^^^^^^^^^^^^^^^^^^^^^^^^^^^\n  File \"/usr/local/lib/python3.12/site-packages/selenium/webdriver/chrome/webdriver.py\", line 45, in __init__\n    super().__init__(\n  File \"/usr/local/lib/python3.12/site-packages/selenium/webdriver/chromium/webdriver.py\", line 53, in __init__\n    self.service.start()\n  File \"/usr/local/lib/python3.12/site-packages/selenium/webdriver/common/service.py\", line 109, in start\n    self.assert_process_still_running()\n  File \"/usr/local/lib/python3.12/site-packages/selenium/webdriver/common/service.py\", line 122, in assert_process_still_running\n    raise WebDriverException(f\"Service {self._path} unexpectedly exited. Status code was: {return_code}\")\n","steps":[],"attachments":[],"parameters":[],"stepsCount":0,"attachmentsCount":0,"shouldDisplayMessage":true,"hasContent":true}],"testStage":{"status":"broken","statusMessage":"selenium.common.exceptions.WebDriverException: Message: Service /root/.wdm/drivers/chromedriver/linux64/114.0.5735.90/chromedriver unexpectedly exited. Status code was: 255","statusTrace":"request = <SubRequest 'driver' for <Function test_create_new_user>>\n\n    @pytest.fixture(scope='class', autouse=True)\n    def driver(request):\n        options = Options()\n        options.add_argument(\"--no-sandbox\")\n        options.add_argument(\"window-size=2560,1600\")\n        options.add_argument(\"--headless\")\n        options.add_argument(\"--disable-gpu\")\n        service = Service(ChromeDriverManager().install())\n>       driver = webdriver.Chrome(service=service, options=options)\n\nconftest.py:16: \n_ _ _ _ _ _ _ _ _ _ _ _ _ _ _ _ _ _ _ _ _ _ _ _ _ _ _ _ _ _ _ _ _ _ _ _ _ _ _ _ \n/usr/local/lib/python3.12/site-packages/selenium/webdriver/chrome/webdriver.py:45: in __init__\n    super().__init__(\n/usr/local/lib/python3.12/site-packages/selenium/webdriver/chromium/webdriver.py:53: in __init__\n    self.service.start()\n/usr/local/lib/python3.12/site-packages/selenium/webdriver/common/service.py:109: in start\n    self.assert_process_still_running()\n_ _ _ _ _ _ _ _ _ _ _ _ _ _ _ _ _ _ _ _ _ _ _ _ _ _ _ _ _ _ _ _ _ _ _ _ _ _ _ _ \n\nself = <selenium.webdriver.chrome.service.Service object at 0xffffb6698470>\n\n    def assert_process_still_running(self) -> None:\n        \"\"\"Check if the underlying process is still running.\"\"\"\n        return_code = self.process.poll()\n        if return_code:\n>           raise WebDriverException(f\"Service {self._path} unexpectedly exited. Status code was: {return_code}\")\nE           selenium.common.exceptions.WebDriverException: Message: Service /root/.wdm/drivers/chromedriver/linux64/114.0.5735.90/chromedriver unexpectedly exited. Status code was: 255\n\n/usr/local/lib/python3.12/site-packages/selenium/webdriver/common/service.py:122: WebDriverException","steps":[],"attachments":[{"uid":"cca1ca2b32f50b32","name":"log","source":"cca1ca2b32f50b32.txt","type":"text/plain","size":602}],"parameters":[],"stepsCount":0,"attachmentsCount":1,"shouldDisplayMessage":true,"hasContent":true},"afterStages":[],"labels":[{"name":"feature","value":"Cteate new user"},{"name":"severity","value":"CRITICAL"},{"name":"tag","value":"smoke"},{"name":"parentSuite","value":"test"},{"name":"suite","value":"test_create_custuner"},{"name":"subSuite","value":"TestCreateCostuner"},{"name":"host","value":"393baa2e9476"},{"name":"thread","value":"1-MainThread"},{"name":"framework","value":"pytest"},{"name":"language","value":"cpython3"},{"name":"package","value":"test.test_create_custuner"},{"name":"resultFormat","value":"allure2"}],"parameters":[],"links":[],"hidden":true,"retry":true,"extra":{"categories":[],"tags":["smoke"]},"source":"9dff96bb821c3908.json","parameterValues":[]}